Workbook

Sheet Cost Estimate
B2: Rankin Inlet, Arviat & Chesterfield Inlet — NWI Last Mile Wireless System
B3: Mock Cost Estimate by WBS — 3-Community / 50-Subscriber Solution
B4: Prepared by: Northern Wireless Inc. (NWI) | Reference: NWI-EST-RANKIN-2026 Rev 0 | Basis: WBSWithEstimatesV1.xlsx + Scope of Supply Summary
B6: WBS No | C6: Item | D6: Unit | E6: Qty | F6: Unit Price | G6: Our Cost Total | H6: Cust Cost Total | I6: Profit | J6: Std. Delivery (Cal. Days) | K6: Effort (Hrs) | L6: Notes / Source Mapping
C7: Engineering & Admin
B8: E-SVT | C8: Site visit (2 days) | D8: Each | E8: 1 | F8: 1400 | G8: =E8*F8 -> 1400 | H8: =G8*1.3 -> 1820 | I8: =H8-G8 -> 420 | J8: 2 | K8: 16 | L8: Site study & conceptual design — kickoff site visit
B9: E-SST | C9: Site study | D9: Days | E9: 1 | F9: 2000 | G9: =E9*F9 -> 2000 | H9: =G9*1.3 -> 2600 | I9: =H9-G9 -> 600 | J9: 5 | K9: 40 | L9: Site study & conceptual design
B10: E-SLD | C10: Site layout drawing | D10: Days | E10: 1 | F10: 800 | G10: =E10*F10 -> 800 | H10: =G10*1.3 -> 1040 | I10: =H10-G10 -> 240 | J10: 2 | K10: 16 | L10: Layout drawing and BOM
B11: E-NDD | C11: Network design and drawing | D11: Days | E11: 1 | F11: 1200 | G11: =E11*F11 -> 1200 | H11: =G11*1.3 -> 1560 | I11: =H11-G11 -> 360 | J11: 3 | K11: 24 | L11: Network design and configuration drawings
B12: E-TMN | C12: Technical/Training Manual | D12: Days | E12: 1 | F12: 2000 | G12: =E12*F12 -> 2000 | H12: =G12*1.3 -> 2600 | I12: =H12-G12 -> 600 | J12: 5 | K12: 40 | L12: Training manual documentation
B13: E-BDS | C13: Engineering — Base Station subsystem | D13: Days | E13: 1 | F13: 1200 | G13: =E13*F13 -> 1200 | H13: =G13*1.3 -> 1560 | I13: =H13-G13 -> 360 | J13: 3 | K13: 24 | L13: Coordination — base station (Bandwidth Distribution System) engineering
B14: E-BCS | C14: Engineering — Wired Network subsystem | D14: Days | E14: 1 | F14: 1600 | G14: =E14*F14 -> 1600 | H14: =G14*1.3 -> 2080 | I14: =H14-G14 -> 480 | J14: 4 | K14: 32 | L14: Coordination — wired network / bandwidth control gateway engineering
B15: E-CPE | C15: Engineering — Premise Equipment subsystem | D15: Days | E15: 1 | F15: 400 | G15: =E15*F15 -> 400 | H15: =G15*1.3 -> 520 | I15: =H15-G15 -> 120 | J15: 1 | K15: 8 | L15: Coordination — CPE configuration template for 50 units
B16: PM-COORD* | C16: Project Management & Coordination | D16: Days | E16: 1 | F16: 1600 | G16: =E16*F16 -> 1600 | H16: =G16*1.3 -> 2080 | I16: =H16-G16 -> 480 | J16: 4 | K16: 32 | L16: *By analogy at WBS $400/day rate (no dedicated WBS row); oversees engineering-to-startup handoff
B17: PROC* | C17: Procurement / Purchasing Support | D17: Days | E17: 1 | F17: 800 | G17: =E17*F17 -> 800 | H17: =G17*1.3 -> 1040 | I17: =H17-G17 -> 240 | J17: 2 | K17: 16 | L17: *Matches Sample Cost Template 'Procurement time' line (2 days / $800)
C18: Subtotal — Engineering & Admin | G18: =SUM(G8:G17) -> 13000 | H18: =SUM(H8:H17) -> 16900 | I18: =SUM(I8:I17) -> 3900 | J18: =MAX(J8:J17) -> 5 | K18: =SUM(K8:K17) -> 248
C20: Base Station
B21: C-BDS-APC | C21: Access Point Cabinet | D21: Each | E21: 1 | F21: 2200 | G21: =E21*F21 -> 2200 | H21: =G21*1.3 -> 2860 | I21: =H21-G21 -> 660 | J21: 21 | L21: 1 – Access point & cabinet
B22: C-BDS-WAP | C22: Wireless Access Point / Radio Card | D22: Each | E22: 2 | F22: 2200 | G22: =E22*F22 -> 4400 | H22: =G22*1.3 -> 5720 | I22: =H22-G22 -> 1320 | J22: 21 | L22: 2 – Radio Card (AP radio modules)
B23: C-BDS-ANT | C23: Omni Antenna | D23: Each | E23: 2 | F23: 600 | G23: =E23*F23 -> 1200 | H23: =G23*1.3 -> 1560 | I23: =H23-G23 -> 360 | J23: 14 | L23: 2 – Antennas/Amplifier (antenna side)
B24: C-BDS-AMP | C24: Bi-Directional Amplifier | D24: Each | E24: 2 | F24: 800 | G24: =E24*F24 -> 1600 | H24: =G24*1.3 -> 2080 | I24: =H24-G24 -> 480 | J24: 14 | L24: 2 – Antennas/Amplifier (amplifier side)
B25: C-BDS-CBL | C25: Cable Coax | D25: Each | E25: 2 | F25: 150 | G25: =E25*F25 -> 300 | H25: =G25*1.3 -> 390 | I25: =H25-G25 -> 90 | J25: 7 | L25: 2 – Cabling and connectors (cable)
B26: C-BDS-CON | C26: Connectors | D26: Each | E26: 2 | F26: 100 | G26: =E26*F26 -> 200 | H26: =G26*1.3 -> 260 | I26: =H26-G26 -> 60 | J26: 7 | L26: 2 – Cabling and connectors (connectors)
B27: C-BDS-LGP | C27: Lightning Protection | D27: Each | E27: 1 | F27: 150 | G27: =E27*F27 -> 150 | H27: =G27*1.3 -> 195 | I27: =H27-G27 -> 45 | J27: 10 | L27: Power outage protection and power conditioning
B28: C-BDS-POE | C28: Power Over Ethernet / Conditioning | D28: Each | E28: 1 | F28: 200 | G28: =E28*F28 -> 200 | H28: =G28*1.3 -> 260 | I28: =H28-G28 -> 60 | J28: 10 | L28: Power outage protection and power conditioning
B29: C-BRK-ASY | C29: Mast Mounting Bracket Assembly | D29: Each | E29: 1 | F29: 180 | G29: =E29*F29 -> 180 | H29: =G29*1.3 -> 234 | I29: =H29-G29 -> 54 | J29: 3 | K29: 4 | L29: Exclusions: NWI supplies bracket to mount antennas to mast (no full tower in this scope)
B30: I-BDS | C30: Install — Base Station | D30: Each | E30: 1 | F30: 800 | G30: =E30*F30 -> 800 | H30: =G30*1.3 -> 1040 | I30: =H30-G30 -> 240 | J30: 2 | K30: 16 | L30: Installation of equipment (base station)
B31: S-BDS | C31: Startup — Base Station | D31: Each | E31: 1 | F31: 400 | G31: =E31*F31 -> 400 | H31: =G31*1.3 -> 520 | I31: =H31-G31 -> 120 | J31: 1 | K31: 8 | L31: On-the-ground / installed on-site testing (base station)
C32: Subtotal — Base Station | G32: =SUM(G21:G31) -> 11630 | H32: =SUM(H21:H31) -> 15119 | I32: =SUM(I21:I31) -> 3489 | J32: =MAX(J21:J31) -> 21 | K32: =SUM(K21:K31) -> 28
C34: Wired Network
B35: C-BCS-CHW | C35: Bandwidth Control Gateway — Hardware | D35: Each | E35: 1 | F35: 4000 | G35: =E35*F35 -> 4000 | H35: =G35*1.3 -> 5200 | I35: =H35-G35 -> 1200 | J35: 21 | L35: Bandwidth control gateway
B36: C-BCS-CSW | C36: Bandwidth Control Gateway — Software | D36: Each | E36: 1 | F36: 1500 | G36: =E36*F36 -> 1500 | H36: =G36*1.3 -> 1950 | I36: =H36-G36 -> 450 | J36: 14 | L36: Bandwidth control gateway
B37: C-BCS-CBL | C37: Cable — Wired Network | D37: Each | E37: 1 | F37: 300 | G37: =E37*F37 -> 300 | H37: =G37*1.3 -> 390 | I37: =H37-G37 -> 90 | J37: 10 | L37: Wired network cabling
B38: C-BSS-RTR | C38: Router / Main Hub-Switch | D38: Each | E38: 1 | F38: 2500 | G38: =E38*F38 -> 2500 | H38: =G38*1.3 -> 3250 | I38: =H38-G38 -> 750 | J38: 21 | L38: Main Hub/switch
B39: C-BCS-LGP* | C39: Power Outage Protection & Conditioning | D39: Each | E39: 1 | F39: 150 | G39: =E39*F39 -> 150 | H39: =G39*1.3 -> 195 | I39: =H39-G39 -> 45 | J39: 10 | L39: *Wired network side; cost by analogy to C-BDS-LGP (no dedicated WBS row)
B40: I-BCS | C40: Install — Wired Network | D40: Each | E40: 1 | F40: 2000 | G40: =E40*F40 -> 2000 | H40: =G40*1.3 -> 2600 | I40: =H40-G40 -> 600 | J40: 3 | K40: 24 | L40: Installation of equipment / configuration (wired network)
B41: S-BCS | C41: Startup — Wired Network | D41: Each | E41: 1 | F41: 800 | G41: =E41*F41 -> 800 | H41: =G41*1.3 -> 1040 | I41: =H41-G41 -> 240 | J41: 2 | K41: 16 | L41: On-the-ground / installed on-site testing (wired network)
C42: Subtotal — Wired Network | G42: =SUM(G35:G41) -> 11250 | H42: =SUM(H35:H41) -> 14625 | I42: =SUM(I35:I41) -> 3375 | J42: =MAX(J35:J41) -> 21 | K42: =SUM(K35:K41) -> 40
C44: Premise Equipment (Qty 50 Subscribers)
B45: C-CPE-CWD | C45: Modem/Radio (Wireless Device) | D45: Each | E45: 50 | F45: 175 | G45: =E45*F45 -> 8750 | H45: =G45*1.3 -> 11375 | I45: =H45-G45 -> 2625 | J45: 14 | L45: 50 – Modem/Radio
...

Sheet Raw Data
A1: TBID | B1: tbMDWBS | C1: tbMDPhase | D1: Sub-Project or WorkPackage | E1: tbName | F1: tbBudget | G1: tbDuration | H1: tbWork | I1: tbMDNotes
A2: 100 | B2: C-BCS-CBL | C2: Equipment Procurement | D2: =_xlfn.XLOOKUP(LEFT(B2,5),WBSNew!$D:$D,WBSNew!$E:$E,"Not found") -> Bandwidth Control System | E2: Cable — Wired Network | F2: 300 | G2: 10 | H2: 0 | I2: Wired network cabling
A3: 101 | B3: C-BCS-CHW | C3: Equipment Procurement | D3: =_xlfn.XLOOKUP(LEFT(B3,5),WBSNew!$D:$D,WBSNew!$E:$E,"Not found") -> Bandwidth Control System | E3: Bandwidth Control Gateway — Hardware | F3: 4000 | G3: 21 | H3: 0 | I3: Bandwidth control gateway
A4: 102 | B4: C-BCS-CSW | C4: Equipment Procurement | D4: =_xlfn.XLOOKUP(LEFT(B4,5),WBSNew!$D:$D,WBSNew!$E:$E,"Not found") -> Bandwidth Control System | E4: Bandwidth Control Gateway — Software | F4: 1500 | G4: 14 | H4: 0 | I4: Bandwidth control gateway
A5: 103 | B5: C-BCS-LGP* | C5: Equipment Procurement | D5: =_xlfn.XLOOKUP(LEFT(B5,5),WBSNew!$D:$D,WBSNew!$E:$E,"Not found") -> Bandwidth Control System | E5: Power Outage Protection & Conditioning | F5: 150 | G5: 10 | H5: 0 | I5: *Wired network side; cost by analogy to C-BDS-LGP (no dedicated WBS row)
A6: 104 | B6: C-BDS-AMP | C6: Equipment Procurement | D6: =_xlfn.XLOOKUP(LEFT(B6,5),WBSNew!$D:$D,WBSNew!$E:$E,"Not found") -> Bandwidth Distrubution System | E6: Bi-Directional Amplifier | F6: 1600 | G6: 14 | H6: 0 | I6: 2 – Antennas/Amplifier (amplifier side)
A7: 105 | B7: C-BDS-ANT | C7: Equipment Procurement | D7: =_xlfn.XLOOKUP(LEFT(B7,5),WBSNew!$D:$D,WBSNew!$E:$E,"Not found") -> Bandwidth Distrubution System | E7: Omni Antenna | F7: 1200 | G7: 14 | H7: 0 | I7: 2 – Antennas/Amplifier (antenna side)
A8: 106 | B8: C-BDS-APC | C8: Equipment Procurement | D8: =_xlfn.XLOOKUP(LEFT(B8,5),WBSNew!$D:$D,WBSNew!$E:$E,"Not found") -> Bandwidth Distrubution System | E8: Access Point Cabinet | F8: 2200 | G8: 21 | H8: 0 | I8: 1 – Access point & cabinet
A9: 107 | B9: C-BDS-CBL | C9: Equipment Procurement | D9: =_xlfn.XLOOKUP(LEFT(B9,5),WBSNew!$D:$D,WBSNew!$E:$E,"Not found") -> Bandwidth Distrubution System | E9: Cable Coax | F9: 300 | G9: 7 | H9: 0 | I9: 2 – Cabling and connectors (cable)
A10: 108 | B10: C-BDS-CON | C10: Equipment Procurement | D10: =_xlfn.XLOOKUP(LEFT(B10,5),WBSNew!$D:$D,WBSNew!$E:$E,"Not found") -> Bandwidth Distrubution System | E10: Connectors | F10: 200 | G10: 7 | H10: 0 | I10: 2 – Cabling and connectors (connectors)
A11: 109 | B11: C-BDS-LGP | C11: Equipment Procurement | D11: =_xlfn.XLOOKUP(LEFT(B11,5),WBSNew!$D:$D,WBSNew!$E:$E,"Not found") -> Bandwidth Distrubution System | E11: Lightning Protection | F11: 150 | G11: 10 | H11: 0 | I11: Power outage protection and power conditioning
A12: 110 | B12: C-BDS-POE | C12: Equipment Procurement | D12: =_xlfn.XLOOKUP(LEFT(B12,5),WBSNew!$D:$D,WBSNew!$E:$E,"Not found") -> Bandwidth Distrubution System | E12: Power Over Ethernet / Conditioning | F12: 200 | G12: 10 | H12: 0 | I12: Power outage protection and power conditioning
A13: 111 | B13: C-BDS-WAP | C13: Equipment Procurement | D13: =_xlfn.XLOOKUP(LEFT(B13,5),WBSNew!$D:$D,WBSNew!$E:$E,"Not found") -> Bandwidth Distrubution System | E13: Wireless Access Point / Radio Card | F13: 4400 | G13: 21 | H13: 0 | I13: 2 – Radio Card (AP radio modules)
... A38: 137 | B38: E-TMN | C38: Engineerring | D38: =_xlfn.XLOOKUP(LEFT(B38,5),WBSNew!$D:$D,WBSNew!$E:$E,"Not found") -> Technical Manual | E38: Technical/Training Manual | F38: 2000 | G38: 5 | H38: 40 | I38: Training manual documentation
G39: 20

Sheet WBSNew
A1: L1 | B1: L2 | C1: L3 | D1: WBS No | E1: WBSTitle | F1: Standard Cost | G1: Standard Delivery in Calendar Days | H1: Effort/Hours
A2: C | E2: Components
A3: C | B3: BBS | D3: C-BBS | E3: Bandwidth Backhaul System | F3: =SUM(F4,F5,F6) -> 4300 | G3: =MAX(G4,G5,G6) -> 21
A4: C | B4: BBS | C4: ANT | D4: C-BBS-ANT | E4: Antenna - Bandwidth Backhaul System | F4: 4000 | G4: 21
A5: C | B5: BBS | C5: CBL | D5: C-BBS-CBL | E5: Cable Coax - Bandwidth Backhaul System | F5: 200 | G5: 10
A6: C | B6: BBS | C6: CON | D6: C-BBS-CON | E6: Connectors - Bandwidth Backhaul System | F6: 100 | G6: 7
A7: C | B7: BCS | D7: C-BCS | E7: Bandwidth Control System | F7: =SUM(F8,F9,F10) -> 5800 | G7: =MAX(G8,G9,G10) -> 21
A8: C | B8: BCS | C8: CBL | D8: C-BCS-CBL | E8: Cables - Bandwidth Control System | F8: 300 | G8: 10
A9: C | B9: BCS | C9: CHW | D9: C-BCS-CHW | E9: Computer Hardware - Bandwidth Control System | F9: 4000 | G9: 21
A10: C | B10: BCS | C10: CSW | D10: C-BCS-CSW | E10: Computer SW - Bandwidth Control System | F10: 1500 | G10: 14
A11: C | B11: BDS | D11: C-BDS | E11: Bandwidth Distrubution System | F11: =SUM(F12,F13,F14,F15,F16,F17,F18,F19) -> 6400 | G11: =MAX(G12,G13,G14,G15,G16,G17,G18,G19) -> 21
A12: C | B12: BDS | C12: AMP | D12: C-BDS-AMP | E12: Amplifier - Bandwidth Distrubution System | F12: 800 | G12: 14
A13: C | B13: BDS | C13: ANT | D13: C-BDS-ANT | E13: Antenna - Bandwidth Distrubution System | F13: 600 | G13: 14
A14: C | B14: BDS | C14: APC | D14: C-BDS-APC | E14: Access Point Cabinet - Bandwidth Distrubution System | F14: 2200 | G14: 21
A15: C | B15: BDS | C15: CBL | D15: C-BDS-CBL | E15: Cable - Bandwidth Distrubution System | F15: 150 | G15: 7
A16: C | B16: BDS | C16: CON | D16: C-BDS-CON | E16: Connectors - Bandwidth Distrubution System | F16: 100 | G16: 7
A17: C | B17: BDS | C17: LGP | D17: C-BDS-LGP | E17: Lightning Protectors - Bandwidth Distrubution System | F17: 150 | G17: 10
A18: C | B18: BDS | C18: POE | D18: C-BDS-POE | E18: Power Over Ethernet - Bandwidth Distrubution System | F18: 200 | G18: 10
A19: C | B19: BDS | C19: WAP | D19: C-BDS-WAP | E19: Wireless Access Point - Bandwidth Distrubution System | F19: 2200 | G19: 21
A20: C | B20: BSS | D20: C-BSS | E20: Bandwidth Supply system | F20: =SUM(F21,F22,F23) -> 10800 | G20: =MAX(G21,G22,G23) -> 30
A21: C | B21: BSS | C21: CBL | D21: C-BSS-CBL | E21: Cable - Bandwidth Supply system | F21: 300 | G21: 10
A22: C | B22: BSS | C22: EQB | D22: C-BSS-EQB | E22: Equipment Building - Bandwidth Supply System | F22: 8000 | G22: 30
A23: C | B23: BSS | C23: RTR | D23: C-BSS-RTR | E23: Router - Bandwidth Supply system | F23: 2500 | G23: 21
A24: C | B24: CPE | D24: C-CPE | E24: Customer Premise Equipment | F24: =SUM(F25,F26,F27,F28) -> 223 | G24: =MAX(G25,G26,G27,G28) -> 14
A25: C | B25: CPE | C25: ANT | D25: C-CPE-ANT | E25: Antenna - Customer Premise Equipment | F25: 25 | G25: 14
A26: C | B26: CPE | C26: BRK | D26: C-CPE-BRK | E26: Brackets - Customer Premise Equipment | F26: 15 | G26: 7
A27: C | B27: CPE | C27: CBL | D27: C-CPE-CBL | E27: Cable - Customer Premise Equipment | F27: 8 | G27: 7
A28: C | B28: CPE | C28: CWD | D28: C-CPE-CWD | E28: Wireless Device - Customer Premise Equipment | F28: 175 | G28: 14
A29: C | B29: NSS | D29: C-NSS | E29: Network Server System | F29: =SUM(F30,F31) -> 5500 | G29: =MAX(G30,G31) -> 21
A30: C | B30: NSS | C30: CHW | D30: C-NSS-CHW | E30: Computer Hardware - Network Server System | F30: 4000 | G30: 21
A31: C | B31: NSS | C31: CSW | D31: C-NSS-CSW | E31: Computer Software - Network Server System | F31: 1500 | G31: 14
A32: C | B32: TWR | D32: C-TWR | E32: Tower System | F32: =SUM(F33,F34,F35,F36,F37) -> 14700 | G32: =MAX(G33,G34,G35,G36,G37) -> 30
A33: C | B33: TWR | C33: FRM | D33: C-TWR-FRM | E33: Tower Frame - Tower System | F33: 6000 | G33: 30
A34: C | B34: TWR | C34: BLD | D34: C-TWR-BLD | E34: Building - Tower System | F34: 4000 | G34: 30
A35: C | B35: TWR | C35: BRK | D35: C-TWR-BRK | E35: Brackets - Tower System | F35: 200 | G35: 10
A36: C | B36: TWR | C36: FDN | D36: C-TWR-FDN | E36: Foundaton - Tower System | F36: 3000 | G36: 21
A37: C | B37: TWR | C37: FEN | D37: C-TWR-FEN | E37: Fence - Tower System | F37: 1500 | G37: 14
A38: C | B38: UCS | D38: C-UCS | E38: Unified Communication System | F38: =SUM(F39,F40,F41,F42,F43,F44,F45) -> 12850 | G38: =MAX(G39,G40,G41,G42,G43,G44,G45) -> 21
A39: C | B39: UCS | C39: CBL | D39: C-UCS-CBL | E39: Cable - Unified Communication System | F39: 200 | G39: 10
A40: C | B40: UCS | C40: CHW | D40: C-UCS-CHW | E40: Computer Hardware - Unified Communication System | F40: 2500 | G40: 21
...
